<?xml version="1.0" ?>
<!-- =================================================================================== -->
<!-- |    This document was autogenerated by xacro from xacro/iiwa7.urdf.xacro         | -->
<!-- |    EDITING THIS FILE BY HAND IS NOT RECOMMENDED                                 | -->
<!-- =================================================================================== -->
<robot name="2link_robot">
	
	<material name="black">
		<color rgba="0 0 0 0.7"/>
	</material>
	<material name="white">
		<color rgba="1 1 1 0.7"/>
	</material>

    <link name="base">
    </link>

	<link name="arm1">
		<visual>
			<geometry>
				<box size="1 .05 .05"/>
			</geometry>
			<origin rpy="0 0 0" xyz="0.5 0 0"/>
			<material name="black"/>
		</visual>
        <inertial>
            <origin rpy="0 0 0" xyz="0.5 0 0"/>
            <mass value="1"/>
            <inertia ixx="0.001" ixy="0.0" ixz="0.0" iyy="0.001" iyz="0.0" izz="0.001"/>
        </inertial>
	</link>

	<joint name="baseHinge" type="revolute">
        <origin rpy="0 0 0"  xyz="0 0 0.15"/>
		<axis xyz="0 0 1"/>
		<parent link="base"/>
		<child link="arm1"/>
		<limit effort="20" lower="-2.9670597283903604" upper="2.9670597283903604" velocity="10"/>
        <dynamics damping="0.5"/>
	</joint>

	<link name="arm2">
		<visual>
			<geometry>
				<box size="1 .05 .05"/>
			</geometry>
			<origin rpy="0 0 0" xyz="0.5 0 0"/>
			<material name="white"/>
		</visual>
        <inertial>
            <origin rpy="0 0 0" xyz="0.5 0 0"/>
            <mass value="1"/>
            <inertia ixx="0.001" ixy="0.0" ixz="0.0" iyy="0.001" iyz="0.0" izz="0.001"/>
        </inertial>
	</link>

	<joint name="interArm" type="revolute">
		<axis xyz="0 0 1"/>
		<parent link="arm1"/>
		<child link="arm2"/>
		<origin rpy="0 0 0" xyz="1 0 0"/>
		<limit effort="20" lower="-2.9670597283903604" upper="2.9670597283903604" velocity="10"/>
        <dynamics damping="0.5"/>
	</joint>

	<link name="endEffector">
	    <inertial>
          <origin rpy="0 0 0" xyz="0 0 0"/>
          <mass value="0"/>
          <inertia ixx="0" ixy="0" ixz="0" iyy="0" iyz="0" izz="0"/>
        </inertial>

	</link>

	<joint name="ee_joint" type="fixed">
		<parent link="arm2"/>
		<child link="endEffector"/>
		<origin rpy="0 0 0" xyz="0 0 0.05"/>
	</joint>

</robot>


